---
title: "Exception"
description: "Exceptions and exception handling in ReScript"
canonical: "/docs/manual/v12.0.0/exception"
---

# Exception

Exceptions are just a special kind of variant, thrown in **exceptional** cases (don't abuse them!). Consider using the [`option`](null-undefined-option.mdx) or [`result`](api/core/result) type for recoverable errors.

You can create your own exceptions like you'd make a variant (exceptions need to be capitalized too).

<CodeTab labels={["ReScript", "JS Output"]}>

```res example
exception InputClosed(string)
// later on
throw(InputClosed("The stream has closed!"))
```
```js
import * as Primitive_exceptions from "./stdlib/Primitive_exceptions.js";

let InputClosed = /* @__PURE__ */Primitive_exceptions.create("Playground.InputClosed");

throw {
  RE_EXN_ID: InputClosed,
  _1: "The stream has closed!",
  Error: new Error()
};
```

</CodeTab>

## Built-in Exceptions

ReScript has some built-in exceptions:

### `Not_found`

<CodeTab labels={["ReScript", "JS Output"]}>

```res prelude
let getItem = (item: int) =>
  if (item === 3) {
    // return the found item here
    1
  } else {
    throw(Not_found)
  }

let result =
  try {
    getItem(2)
  } catch {
  | Not_found => 0 // Default value if getItem throws
  }
```
```js
import * as Primitive_exceptions from "./stdlib/Primitive_exceptions.js";

function getItem(item) {
  if (item === 3) {
    return 1;
  }
  throw {
    RE_EXN_ID: "Not_found",
    Error: new Error()
  };
}

let result;

try {
  result = getItem(2);
} catch (raw_exn) {
  let exn = Primitive_exceptions.internalToException(raw_exn);
  if (exn.RE_EXN_ID === "Not_found") {
    result = 0;
  } else {
    throw exn;
  }
}
```

</CodeTab>

Note that the above is just for demonstration purposes; in reality, you'd return an `option<int>` directly from `getItem` and avoid the `try` altogether.

You can directly match on exceptions _while_ getting another return value from a function:

<CodeTab labels={["ReScript", "JS Output"]}>

```res prelude
switch list{1, 2, 3}->List.getExn(4) {
| item => Console.log(item)
| exception Not_found => Console.log("No such item found!")
}
```
```js
import * as Stdlib_List from "./stdlib/Stdlib_List.js";
import * as Primitive_exceptions from "./stdlib/Primitive_exceptions.js";

let exit = 0;

let item;

try {
  item = Stdlib_List.getExn({
    hd: 1,
    tl: {
      hd: 2,
      tl: {
        hd: 3,
        tl: /* [] */0
      }
    }
  }, 4);
  exit = 1;
} catch (raw_exn) {
  let exn = Primitive_exceptions.internalToException(raw_exn);
  if (exn.RE_EXN_ID === "Not_found") {
    console.log("No such item found!");
  } else {
    throw exn;
  }
}

if (exit === 1) {
  console.log(item);
}
```

</CodeTab>

### `Invalid_argument`

Used to check if argument is valid. This exception takes a string.

<CodeTab labels={["ReScript", "JS Output"]}>
```res example
let divide = (a, b) =>
  if b == 0 {
    throw(Invalid_argument("Denominator is zero"))
  } else {
    a / b
  }

// catch error
try divide(2, 0)->Console.log catch {
| Invalid_argument(msg) => Console.log(msg) // Denominator is zero
}
```

```js
import * as Primitive_int from "./stdlib/Primitive_int.js";
import * as Primitive_exceptions from "./stdlib/Primitive_exceptions.js";

function divide(a, b) {
  if (b === 0) {
    throw {
      RE_EXN_ID: "Invalid_argument",
      _1: "Denominator is zero",
      Error: new Error()
    };
  }
  return Primitive_int.div(a, b);
}

try {
  console.log(divide(2, 0));
} catch (raw_msg) {
  let msg = Primitive_exceptions.internalToException(raw_msg);
  if (msg.RE_EXN_ID === "Invalid_argument") {
    console.log(msg._1);
  } else {
    throw msg;
  }
}
```

</CodeTab>

### `Assert_failure`

Thrown when you use `assert(condition)` and `condition` is false. The arguments
are the location of the `assert` in the source code (file name, line number, column number).

<CodeTab labels={["ReScript", "JS Output"]}>

```res example
let decodeUser = (json: JSON.t) =>
  switch json {
  | Object(userDict) =>
    switch (userDict->Dict.get("name"), userDict->Dict.get("age")) {
    | (Some(String(name)), Some(Number(age))) => (name, age->Float.toInt)
    | _ => assert(false)
    }
  | _ => assert(false)
  }


try decodeUser(%raw("{}"))->Console.log catch {
| Assert_failure(loc) => Console.log(loc) // ("filename", line, col)
}
```

```js
import * as Primitive_exceptions from "./stdlib/Primitive_exceptions.js";

function decodeUser(json) {
  if (typeof json === "object" && json !== null && !Array.isArray(json)) {
    let match = json["name"];
    let match$1 = json["age"];
    if (typeof match === "string" && typeof match$1 === "number") {
      return [
        match,
        match$1 | 0
      ];
    }
    throw {
      RE_EXN_ID: "Assert_failure",
      _1: [
        "playground.res",
        6,
        11
      ],
      Error: new Error()
    };
  }
  throw {
    RE_EXN_ID: "Assert_failure",
    _1: [
      "playground.res",
      8,
      9
    ],
    Error: new Error()
  };
}

try {
  console.log(decodeUser({}));
} catch (raw_loc) {
  let loc = Primitive_exceptions.internalToException(raw_loc);
  if (loc.RE_EXN_ID === "Assert_failure") {
    console.log(loc._1);
  } else {
    throw loc;
  }
}
```

</CodeTab>

### `Failure`

Exception thrown to signal that the given arguments do not make sense. This
exception takes a string as an argument.


<CodeTab labels={["ReScript", "JS Output"]}>
```res example
let isValidEmail = email => {
  let hasAtSign = String.includes(email, "@")
  let hasDot = String.includes(email, ".")
  if !(hasAtSign && hasDot) {
    throw(Failure("Invalid email address"))
  } else {
    true
  }
}


let isValid = try isValidEmail("rescript.org") catch {
| Failure(msg) => {
    Console.error(msg)
    false
  }
}
```

```js
import * as Primitive_exceptions from "./stdlib/Primitive_exceptions.js";

function isValidEmail(email) {
  let hasAtSign = email.includes("@");
  let hasDot = email.includes(".");
  if (hasAtSign && hasDot) {
    return true;
  }
  throw {
    RE_EXN_ID: "Failure",
    _1: "Invalid email address",
    Error: new Error()
  };
}

let isValid;

try {
  isValid = isValidEmail("rescript.org");
} catch (raw_msg) {
  let msg = Primitive_exceptions.internalToException(raw_msg);
  if (msg.RE_EXN_ID === "Failure") {
    console.error(msg._1);
    isValid = false;
  } else {
    throw msg;
  }
}
```

</CodeTab>

### `Division_by_zero`

Exception thrown by integer division and remainder operations when their second argument is zero.


<CodeTab labels={["ReScript", "JS Output"]}>
```res example
// ReScript throws `Division_by_zero` if the denominator is zero
let result = try Some(10 / 0) catch {
| Division_by_zero => None
}

Console.log(result) // None
```

```js
import * as Primitive_int from "./stdlib/Primitive_int.js";
import * as Primitive_exceptions from "./stdlib/Primitive_exceptions.js";

let result;

try {
  result = Primitive_int.div(10, 0);
} catch (raw_exn) {
  let exn = Primitive_exceptions.internalToException(raw_exn);
  if (exn.RE_EXN_ID === "Division_by_zero") {
    result = undefined;
  } else {
    throw exn;
  }
}

console.log(result);
```

</CodeTab>

## Catching JS Exceptions

To distinguish between JavaScript exceptions and ReScript exceptions, ReScript namespaces JS exceptions under the `JsExn(payload)` variant. To catch an exception thrown from the JS side:


Throw an exception from JS:

```js
// Example.js

exports.someJsFunctionThatThrows = () => {
    throw new Error("A Glitch in the Matrix!");
}
```

Then catch it from ReScript:

```res
// import the method in Example.js
@module("./Example") 
external someJsFunctionThatThrows: () => unit = "someJsFunctionThatThrows"

try {
  // call the external method
  someJSFunctionThatThrows()
} catch {
| JsExn(exn) =>
  switch JsExn.message(exn) {
  | Some(m) => Console.log("Caught a JS exception! Message: " ++ m)
  | None => ()
  }
}
```

The payload `exn` here is of type `unknown` since in JS you can throw anything. To operate on `exn`, do like the code above by using the standard library's [`JsExn`](api/core/jsexn) module's helpers
or use [`Type.Classify.classify`](api/core/type/classify#value-classify) to get more information about the runtime type of `exn`.

## Throw a JS Exception

### Throw a JS Error

`throw(MyException)` throws a ReScript exception. To throw a JavaScript error (whatever your purpose is), use `JsError.throwWithMessage`:

<CodeTab labels={["ReScript", "JS Output"]}>

```res example
let myTest = () => {
  JsError.throwWithMessage("Hello!")
}
```
```js
import * as Stdlib_JsError from "./stdlib/Stdlib_JsError.js";

function myTest() {
  return Stdlib_JsError.throwWithMessage("Hello!");
}
```

</CodeTab>

Then you can catch it from the JS side:

```js
// after importing `myTest`...
try {
  myTest()
} catch (e) {
  console.log(e.message) // "Hello!"
}
```

### Throw a value that is not an JS Error

If you want to throw any value that is not a valid JS Error, use `JsExn.throw`:

<CodeTab labels={["ReScript", "JS Output"]}>

```res example
let myTest = () => {
  JsExn.throw("some non-error value!")
}
```
```js
function myTest() {
  throw "some non-error value!";
}
```

</CodeTab>

Then you can catch it from the JS side:

```js
// after importing `myTest`...
try {
  myTest()
} catch (message) {
  console.log(message) // "Hello!"
}
```

## Catch ReScript Exceptions from JS

The previous section is less useful than you think; to let your JS code work with your exception-throwing ReScript code, the latter doesn't actually need to throw a JS exception. ReScript exceptions can be used by JS code!

<CodeTab labels={["ReScript", "JS Output"]}>

```res example
exception BadArgument({myMessage: string})

let myTest = () => {
  throw(BadArgument({myMessage: "Oops!"}))
}
```
```js
import * as Primitive_exceptions from "./stdlib/Primitive_exceptions.js";

let BadArgument = /* @__PURE__ */Primitive_exceptions.create("Playground.BadArgument");

function myTest() {
  throw {
    RE_EXN_ID: BadArgument,
    myMessage: "Oops!",
    Error: new Error()
  };
}
```

</CodeTab>

Then, in your JS:

```js
// after importing `myTest`...
try {
  myTest()
} catch (e) {
  console.log(e.myMessage) // "Oops!"
  console.log(e.Error.stack) // the stack trace
}
```

> Note: `RE_EXN_ID` is an internal field for bookkeeping purposes. Don't use it on the JS side. Use the other fields.

The above `BadArgument` exception takes an inline record type. We special-case compile the exception as `{RE_EXN_ID, myMessage, Error}` for good ergonomics. If the exception instead took ordinary positional arguments, l like the standard library's `Invalid_argument("Oops!")`, which takes a single argument, the argument is compiled to JS as the field `_1` instead. A second positional argument would compile to `_2`, etc.

## Tips & Tricks

When you have ordinary variants, you often don't **need** exceptions. For example, instead of throwing when `item` can't be found in a collection, try to return an `option<item>` (`None` in this case) instead.

### Catch Both ReScript and JS Exceptions in the Same `catch` Clause

```res
try {
  someOtherJSFunctionThatThrows()
} catch {
| Not_found => ... // catch a ReScript exception
| Invalid_argument(_) => ... // catch a second ReScript exception
| JsExn(exn) => ... // catch the JS exception
}
```

This technically works, but hopefully you don't ever have to work with such code...
